<?xml version='1.0'?>

<robot name="udacity_bot" xmlns:xacro="http://www.ros.org/wiki/xacro">

<!-- Configure differential drive controller Gazebo plugin -->
<xacro:arg name="odometryTopic" default="odom" />
<xacro:arg name="odometryFrame" default="odom" />
<xacro:arg name="robotBaseFrame" default="robot_footprint" />
<xacro:arg name="diff_drive_publishTf" default="true" />
<xacro:arg name="diff_drive_publishOdomTF" default="true" />

<!-- Determine presence of RGB camera sensor -->
<xacro:arg name="add_camera_sensor" default="true" />

<!-- Determine presence of Hokuyo laser sensor -->
<xacro:arg name="add_laser_sensor" default="true" />

<!-- Configure ground truth odometry Gazebo plugin -->
<xacro:arg name="p3d_base_controller_enabled" default="false" />

<xacro:include filename="$(find udacity_bot)/urdf/udacity_bot.gazebo" />

<xacro:if value="$(arg p3d_base_controller_enabled)">
<xacro:include filename="$(find udacity_bot)/urdf/p3d_base_controller.gazebo" />
</xacro:if>

<!-- Determine the name of the robot's root link -->
  <link name="robot_footprint"></link>

  <joint name="robot_footprint_joint" type="fixed">
    <origin xyz="0 0 0.12" rpy="0 0 0" />
    <parent link="robot_footprint"/>
    <child link="chassis" />
  </joint>

  <link name='chassis'>
    <pose>0 0 0 0 0 0</pose>

    <inertial>
      <mass value="15.0"/>
      <origin xyz="0.0 0 0" rpy=" 0 0 0"/>
      <inertia
          ixx="0.1" ixy="0" ixz="0"
          iyy="0.1" iyz="0"
          izz="0.1"
      />
    </inertial>

    <collision name='collision'>
      <origin xyz="0 0 0" rpy=" 0 0 0"/> 
      <geometry>
        <box size=".4 .2 .12"/>
      </geometry>
    </collision>

    <visual name='chassis_visual'>
      <origin xyz="0 0 0" rpy=" 0 0 0"/>
      <geometry>
        <box size=".4 .2 .12"/>
      </geometry>
    </visual>

    <collision name='back_caster_collision'>
      <origin xyz="-0.15 0 -0.1" rpy=" 0 0 0"/>
      <geometry>
        <sphere radius="0.0499"/>
      </geometry>
    </collision>

    <visual name='back_caster_visual'>
      <origin xyz="-0.15 0 -0.1" rpy=" 0 0 0"/>
      <geometry>
        <sphere radius="0.05"/>
      </geometry>
    </visual>

    <collision name='front_caster_collision'>
      <origin xyz="0.15 0 -0.1" rpy=" 0 0 0"/>
      <geometry>
        <sphere radius="0.0499"/>
      </geometry>
    </collision>

    <visual name='front_caster_visual'>
      <origin xyz="0.15 0 -0.1" rpy=" 0 0 0"/>
      <geometry>
        <sphere radius="0.05"/>
      </geometry>
    </visual>

  </link>

<joint type="continuous" name="left_wheel_hinge">
    <origin xyz="0 0.15 -0.05" rpy="0 0 0"/>
    <child link="left_wheel"/>
    <parent link="chassis"/>
    <axis xyz="0 1 0" rpy="0 0 0"/>
    <limit effort="10000" velocity="1000"/>
    <dynamics damping="1.0" friction="1.0"/>
  </joint>

<link name='left_wheel'>
    <pose>0 0 0.1 0 0 0</pose>

    <inertial>
      <mass value="5.0"/>
      <origin xyz="0.0 0 0" rpy=" 0 1.5707 1.5707"/>
      <inertia
          ixx="0.1" ixy="0" ixz="0"
          iyy="0.1" iyz="0"
          izz="0.1"
      />
    </inertial>

    <collision name='left_wheel_collision'>
      <origin xyz="0 0 0" rpy=" 0 1.5707 1.5707"/>
      <geometry>
        <cylinder radius="0.1" length="0.05"/>
      </geometry>
    </collision>

    <visual name='left_wheel_visual'>
      <origin xyz="0.0 0 0" rpy=" 0 1.5707 1.5707"/>
      <geometry>
        <cylinder radius="0.1" length="0.05"/>
      </geometry>
    </visual>
  </link>

<joint type="continuous" name="right_wheel_hinge">
    <origin xyz="0 -0.15 -0.05" rpy="0 0 0"/>
    <child link="right_wheel"/>
    <parent link="chassis"/>
    <axis xyz="0 1 0" rpy="0 0 0"/>
    <limit effort="10000" velocity="1000"/>
    <dynamics damping="1.0" friction="1.0"/>
  </joint>

<link name='right_wheel'>
    <pose>0 0 0.1 0 0 0</pose>

    <inertial>
      <mass value="5.0"/>
      <origin xyz="0.0 0 0" rpy=" 0 1.5707 1.5707"/>
      <inertia
          ixx="0.1" ixy="0" ixz="0"
          iyy="0.1" iyz="0"
          izz="0.1"
      />
    </inertial>

    <collision name='right_wheel_collision'>
      <origin xyz="0.0 0 0" rpy=" 0 1.5707 1.5707"/>
      <geometry>
        <cylinder radius="0.1" length="0.05"/>
      </geometry>
    </collision>

    <visual name='right_wheel_visual'>
      <origin xyz="0.0 0 0" rpy=" 0 1.5707 1.5707"/>
      <geometry>
        <cylinder radius="0.1" length="0.05"/>
      </geometry>
    </visual>
  </link>


<!-- Add a regular RGB Camera -->

<xacro:if value="$(arg add_camera_sensor)">
  <!-- Add Camera link, joints and mesh -->
  <xacro:include filename="$(find udacity_bot)/urdf/rgb_camera.xacro"/>
  <!-- Add Gazebo Camera Plugin -->
  <xacro:include filename="$(find udacity_bot)/urdf/rgb_camera.gazebo"/>
</xacro:if>

<!-- Add a Hokuyo laser scanner -->

<xacro:if value="$(arg add_laser_sensor)">
  <!-- Add Laser link, joints and mesh -->
  <xacro:include filename="$(find udacity_bot)/urdf/hokuyo_laser.xacro"/>
  <!-- Add Gazebo Laser Plugin -->
  <xacro:include filename="$(find udacity_bot)/urdf/hokuyo_laser.gazebo"/>
</xacro:if>

</robot>
